<?xml version="1.0" ?>
<!-- =================================================================================== -->
<!-- |    This document was autogenerated by xacro from hma_cobot_with_eef.xacro       | -->
<!-- |    EDITING THIS FILE BY HAND IS NOT RECOMMENDED                                 | -->
<!-- =================================================================================== -->
<robot name="mycobot_pro_with_gripper">
  <link name="base">
    <visual>
      <geometry>
        <!--- 0.0 0 -0.04  1.5708 3.14159-->
        <mesh filename="package://mycobot_description/urdf/mycobot_pro_600/base.dae"/>
      </geometry>
      <origin rpy=" 0 0 0" xyz="0 0 0 "/>
    </visual>
    <collision>
      <geometry>
        <!--- 0.0 0 -0.04  1.5708 3.14159-->
        <mesh filename="package://mycobot_description/urdf/mycobot_pro_600/base.dae"/>
      </geometry>
      <origin rpy=" 0 0 0" xyz="0 0 0 "/>
    </collision>
  </link>
  <link name="link1">
    <visual>
      <geometry>
        <mesh filename="package://mycobot_description/urdf/mycobot_pro_600/link1.dae"/>
      </geometry>
      <origin rpy="0 0 3.1415926" xyz="0 0 0 "/>
    </visual>
    <collision>
      <geometry>
        <mesh filename="package://mycobot_description/urdf/mycobot_pro_600/link1.dae"/>
      </geometry>
      <origin rpy=" 0 0 3.1415926" xyz="0 0 0 "/>
    </collision>
  </link>
  <link name="link2">
    <visual>
      <geometry>
        <mesh filename="package://mycobot_description/urdf/mycobot_pro_600/link2.dae"/>
      </geometry>
      <origin rpy=" 3.1415926 0 3.1415926" xyz="0 0 -0.080 "/>
    </visual>
    <collision>
      <geometry>
        <mesh filename="package://mycobot_description/urdf/mycobot_pro_600/link2.dae"/>
      </geometry>
      <origin rpy=" 3.1415926 0 3.1415926" xyz="0 0 -0.080 "/>
    </collision>
  </link>
  <link name="link3">
    <visual>
      <geometry>
        <!--- 0.0 0 -0.04 -->
        <mesh filename="package://mycobot_description/urdf/mycobot_pro_600/link3.dae"/>
      </geometry>
      <origin rpy=" 3.1415926 0 3.1415926" xyz="0 0 -0.0855 "/>
    </visual>
    <collision>
      <geometry>
        <!--- 0.0 0 -0.04 -->
        <mesh filename="package://mycobot_description/urdf/mycobot_pro_600/link3.dae"/>
      </geometry>
      <origin rpy="3.1415926 0 3.1415926" xyz="0 0 -0.0855 "/>
    </collision>
  </link>
  <link name="link4">
    <visual>
      <geometry>
        <!--- 0.0 0 -0.04 -->
        <mesh filename="package://mycobot_description/urdf/mycobot_pro_600/link4.dae"/>
      </geometry>
      <origin rpy=" 0 3.1415926 0" xyz="0 0 0 "/>
    </visual>
    <collision>
      <geometry>
        <!--- 0.0 0 -0.04 -->
        <mesh filename="package://mycobot_description/urdf/mycobot_pro_600/link4.dae"/>
      </geometry>
      <origin rpy=" 0 3.1415926 0" xyz="0 0 0 "/>
    </collision>
  </link>
  <link name="link5">
    <visual>
      <geometry>
        <!--- 0.0 0 -0.04 -->
        <mesh filename="package://mycobot_description/urdf/mycobot_pro_600/link5.dae"/>
      </geometry>
      <origin rpy=" 0  0 1.5707" xyz="0 0  0 "/>
    </visual>
    <collision>
      <geometry>
        <!--- 0.0 0 -0.04 -->
        <mesh filename="package://mycobot_description/urdf/mycobot_pro_600/link5.dae"/>
      </geometry>
      <origin rpy=" 0  0 1.5707" xyz="0 0  0 "/>
    </collision>
  </link>
  <link name="link6">
    <visual>
      <geometry>
        <!--- 0.0 0 -0.04 -->
        <mesh filename="package://mycobot_description/urdf/mycobot_pro_600/link6.dae"/>
      </geometry>
      <material name="grey">
        <color rgba="0.5 0.5 0.5 1"/>
      </material>
      <origin rpy=" 0 -1.5707  0" xyz="0.03 0 0"/>
    </visual>
    <collision>
      <geometry>
        <!--- 0.0 0 -0.04 -->
        <mesh filename="package://mycobot_description/urdf/mycobot_pro_600/link6.dae"/>
      </geometry>
      <material name="grey">
        <color rgba="0.5 0.5 0.5 1"/>
      </material>
      <origin rpy=" 0 -1.5707  0" xyz="0.03 0 0"/>
    </collision>
  </link>
  <joint name="joint1" type="revolute">
    <axis xyz="0 0 1"/>
    <limit effort="1000.0" lower="-3.14" upper="3.14" velocity="0"/>
    <!--limit effort = "1000.0" lower = "-2.26" upper = "1.22" velocity = "0"/-->
    <parent link="base"/>
    <child link="link1"/>
    <origin rpy="0 0 0" xyz="0 0 0.19934"/>
  </joint>
  <joint name="joint2" type="revolute">
    <axis xyz="0 0 -1"/>
    <limit effort="1000.0" lower="-3.14" upper="0.61" velocity="0"/>
    <!--limit effort = "1000.0" lower = "-1.91" upper = "0.61" velocity = "0"/-->
    <!-- <limit effort = "1000.0" lower = "-3.14" upper = "3.14" velocity = "0"/> -->
    <parent link="link1"/>
    <child link="link2"/>
    <!-- <origin xyz= "0 0  0" rpy = "1.5708 -1.5708 0"/>   -->
    <origin rpy="1.5708 0 0" xyz="0 0  0"/>
  </joint>
  <joint name="joint3" type="revolute">
    <axis xyz=" 0 0 -1"/>
    <limit effort="1000.0" lower="-2.61" upper="2.618" velocity="0"/>
    <parent link="link2"/>
    <child link="link3"/>
    <origin rpy="0 0 0" xyz="0.25 0 0   "/>
  </joint>
  <joint name="joint4" type="revolute">
    <axis xyz=" 0 0 -1"/>
    <limit effort="1000.0" lower="-4.53" upper="1.3962" velocity="0"/>
    <!-- <limit effort = "1000.0" lower = "-2.96" upper = "2.97" velocity = "0"/> -->
    <parent link="link3"/>
    <child link="link4"/>
    <!-- <origin xyz= "0.25 0  -0.1091" rpy = "0 0 1.5708"/>   -->
    <origin rpy="0 0 0" xyz="0.25 0  -0.1091"/>
  </joint>
  <joint name="joint5" type="revolute">
    <axis xyz="0 0 1"/>
    <limit effort="1000.0" lower="-2.93" upper="2.9321" velocity="0"/>
    <parent link="link4"/>
    <child link="link5"/>
    <origin rpy="1.57080 -1.57080 0" xyz="0 -0.108 0"/>
  </joint>
  <joint name="joint6" type="revolute">
    <axis xyz="-1 0 0"/>
    <limit effort="1000.0" lower="-3.03" upper="3.0368" velocity="0"/>
    <parent link="link5"/>
    <child link="link6"/>
    <origin rpy="-1.57080 0 0 " xyz="-0.07586 0 0"/>
  </joint>
  <link name="camera_adaptor">
    <visual>
      <geometry>
        <mesh filename="package://mycobot_description/urdf/camera_attachments/adaptor.dae"/>
      </geometry>
      <origin rpy=" 0 0 0" xyz="0.00 0.00 0.00 "/>
    </visual>
    <collision>
      <geometry>
        <mesh filename="package://mycobot_description/urdf/camera_attachments/adaptor.dae"/>
      </geometry>
      <origin rpy=" 0 0 0" xyz="0.00 0.00 0.00 "/>
    </collision>
  </link>
  <joint name="camera_adaptor_link" type="fixed">
    <parent link="link6"/>
    <child link="camera_adaptor"/>
    <origin rpy="0 3.14 0" xyz="0.000 0 0"/>
  </joint>
  <link name="gripper_base">
    <visual>
      <geometry>
        <mesh filename="package://mycobot_description/urdf/pro_adaptive_gripper/gripper_base.dae"/>
      </geometry>
      <origin rpy=" 0 0 1.5708" xyz="-0.02 0.012 -0.018 "/>
    </visual>
    <collision>
      <geometry>
        <mesh filename="package://mycobot_description/urdf/pro_adaptive_gripper/gripper_base.dae"/>
      </geometry>
      <origin rpy=" 0 0 1.5708" xyz="-0.02 0.012 -0.018 "/>
    </collision>
  </link>
  <link name="gripper_left1">
    <visual>
      <geometry>
        <mesh filename="package://mycobot_description/urdf/pro_adaptive_gripper/gripper_left1.dae"/>
      </geometry>
      <origin rpy=" 0 0 1.5708" xyz="0.036 -0.052 0.0 "/>
    </visual>
    <collision>
      <geometry>
        <mesh filename="package://mycobot_description/urdf/pro_adaptive_gripper/gripper_left1.dae"/>
      </geometry>
      <origin rpy=" 0 0 1.5708" xyz="0.036 -0.052 0.0 "/>
    </collision>
  </link>
  <link name="gripper_left2">
    <visual>
      <geometry>
        <mesh filename="package://mycobot_description/urdf/pro_adaptive_gripper/gripper_left2.dae"/>
      </geometry>
      <origin rpy=" 0 0 1.5708" xyz="0.03 0.024 -0.018 "/>
    </visual>
    <collision>
      <geometry>
        <mesh filename="package://mycobot_description/urdf/pro_adaptive_gripper/gripper_left2.dae"/>
      </geometry>
      <origin rpy=" 0 0 1.5708" xyz="0.03 0.024 -0.018 "/>
    </collision>
  </link>
  <link name="gripper_left3">
    <visual>
      <geometry>
        <mesh filename="package://mycobot_description/urdf/pro_adaptive_gripper/gripper_left3.dae"/>
      </geometry>
      <origin rpy=" 0 3.14159 -1.5708" xyz="0.034 0.0 -0.012 "/>
    </visual>
    <collision>
      <geometry>
        <mesh filename="package://mycobot_description/urdf/pro_adaptive_gripper/gripper_left3.dae"/>
      </geometry>
      <origin rpy=" 0 3.14159 -1.5708" xyz="0.034 0.0 -0.012 "/>
    </collision>
  </link>
  <link name="gripper_right1">
    <visual>
      <geometry>
        <mesh filename="package://mycobot_description/urdf/pro_adaptive_gripper/gripper_right1.dae"/>
      </geometry>
      <origin rpy=" 0 0 1.5708" xyz="-0.072 -0.05 0.0 "/>
    </visual>
    <collision>
      <geometry>
        <mesh filename="package://mycobot_description/urdf/pro_adaptive_gripper/gripper_right1.dae"/>
      </geometry>
      <origin rpy=" 0 0 1.5708" xyz="-0.072 -0.05 0.0 "/>
      <!--origin xyz = "-0.036 -0.052 0.0 " rpy = " 0 0 1.5708"/-->
    </collision>
  </link>
  <link name="gripper_right2">
    <visual>
      <geometry>
        <mesh filename="package://mycobot_description/urdf/pro_adaptive_gripper/gripper_right2.dae"/>
      </geometry>
      <origin rpy=" 0 0 1.5708" xyz="-0.066 0.023 -0.018 "/>
      <!--origin xyz = "-0.03 0.024 -0.018 " rpy = " 0 0 1.5708"/-->
    </visual>
    <collision>
      <geometry>
        <mesh filename="package://mycobot_description/urdf/pro_adaptive_gripper/gripper_right2.dae"/>
      </geometry>
      <origin rpy=" 0 0 1.5708" xyz="-0.066 0.023 -0.018 "/>
      <!--origin xyz = "-0.03 0.024 -0.018 " rpy = " 0 0 1.5708"/-->
    </collision>
  </link>
  <link name="gripper_right3">
    <visual>
      <geometry>
        <mesh filename="package://mycobot_description/urdf/pro_adaptive_gripper/gripper_right3.dae"/>
      </geometry>
      <origin rpy=" 0 3.14159 -1.5708" xyz="0 0.0 -0.012 "/>
      <!--origin xyz = "-0.034 0.0 -0.012 " rpy = " 0 3.14159 -1.5708"/-->
    </visual>
    <collision>
      <geometry>
        <mesh filename="package://mycobot_description/urdf/pro_adaptive_gripper/gripper_right3.dae"/>
      </geometry>
      <origin rpy=" 0 3.14159 -1.5708" xyz="0 0.0 -0.012 "/>
      <!--origin xyz = "-0.034 0.0 -0.012 " rpy = " 0 3.14159 -1.5708"/-->
    </collision>
  </link>
  <joint name="gripper_controller" type="revolute">
    <axis xyz="0 0 1"/>
    <limit effort="1000.0" lower="-0.7" upper="0.3" velocity="0"/>
    <parent link="gripper_base"/>
    <child link="gripper_left3"/>
    <origin rpy="0 0 0" xyz="-0.018 0.016 0"/>
  </joint>
  <!--joint name="gripper_base_to_gripper_left2" type="revolute"-->
  <joint name="gripper_left2" type="revolute">
    <axis xyz="0 0 1"/>
    <limit effort="1000.0" lower="-0.8" upper="0.5" velocity="0"/>
    <parent link="gripper_base"/>
    <child link="gripper_left2"/>
    <origin rpy="0 0 0" xyz="-0.05 -0.01 0"/>
    <mimic joint="gripper_controller" multiplier="1.0" offset="0"/>
  </joint>
  <!--joint name="gripper_left3_to_gripper_left1" type="revolute"-->
  <joint name="gripper_left1" type="revolute">
    <axis xyz="0 0 1"/>
    <limit effort="1000.0" lower="-0.5" upper="0.5" velocity="0"/>
    <parent link="gripper_left3"/>
    <child link="gripper_left1"/>
    <origin rpy="0 0 0" xyz="-0.0356 0.051 -0.018"/>
    <mimic joint="gripper_controller" multiplier="-1.0" offset="0"/>
  </joint>
  <joint name="gripper_right3" type="revolute">
    <axis xyz="0 0 1"/>
    <limit effort="1000.0" lower="-0.3" upper="0.7" velocity="0"/>
    <parent link="gripper_base"/>
    <child link="gripper_right3"/>
    <origin rpy="0 0 0" xyz="0.018 0.016 0"/>
    <mimic joint="gripper_controller" multiplier="-1.0" offset="0"/>
  </joint>
  <joint name="gripper_right2" type="revolute">
    <axis xyz="0 0 1"/>
    <limit effort="1000.0" lower="-0.5" upper="0.8" velocity="0"/>
    <parent link="gripper_base"/>
    <child link="gripper_right2"/>
    <origin rpy="0 0 0" xyz="0.046 -0.01 0"/>
    <mimic joint="gripper_controller" multiplier="-1.0" offset="0"/>
  </joint>
  <joint name="gripper_right1" type="revolute">
    <axis xyz="0 0 1"/>
    <limit effort="1000.0" lower="-0.5" upper="0.5" velocity="0"/>
    <parent link="gripper_right3"/>
    <child link="gripper_right1"/>
    <origin rpy="0 0 0" xyz="0.033 0.051 -0.018"/>
    <mimic joint="gripper_controller" multiplier="1.0" offset="0"/>
  </joint>
  <joint name="flange_to_gripper" type="fixed">
    <parent link="camera_adaptor"/>
    <child link="gripper_base"/>
    <origin rpy="-1.57 1.57 3.14" xyz="0.06 -0.007 0"/>
  </joint>
  <!--extension for eef-->
  <link name="end_effector_link">
    <visual>
      <origin rpy="0 0 0" xyz="0 0 0"/>
      <geometry>
        <box length="0.1" size="0.01 0.01 0.01"/>
      </geometry>
    </visual>
  </link>
  <joint name="end_effector_joint" type="fixed">
    <parent link="camera_adaptor"/>
    <child link="end_effector_link"/>
    <!--origin xyz="0.1 0.0 0.0" rpy="0 1.57 1.57"/> -->
    <!--origin xyz="0.1 0.0 0.0" rpy="3.14 -1.57 1.57"/-->
    <origin rpy="-1.57 0 -1.57" xyz="0.1 0.0 0.0"/>
  </joint>
</robot>
